<?xml version="1.0"?>

<robot name="Robot">

  <link name="base_link">
    <visual>
      <geometry> <box size="0.4 0.2 0.6" />  </geometry>
      <material name="green"><color rgba="0 1 0 1" />  </material>
    </visual>
  </link>

  <joint name="joint_0_1" type="continuous">
    <parent link="base_link" />
    <child link="link_1" />
    <origin xyz="0 0 0.3" rpy = "0 0 0"/>
    <axis xyz="0 0 1" />
    <dynamics damping="0.1" />
  </joint>

  <link name="link_1">
    <inertial>
      <origin xyz="0 0 0" rpy="0 0 0" />
      <mass value="1" />
      <inertia ixx="1" ixy="0" ixz="0" iyy="0.083" iyz="0" izz="1" />
    </inertial>
    <visual>
         <origin xyz="0.5 0 0"/>
         <geometry> <box size="1.0 0.05 0.05" /></geometry>
         <material name="red">  <color rgba="1 0 0 1" /></material>
    </visual>
  </link>

  <joint name="joint_1_2" type="continuous">
    <parent link="link_1" />
    <child link="link_2" />
    <origin xyz="1 0 0" rpy = "0 0 0"/>
    <axis xyz="1 0 0" />
    <dynamics damping="0.1" />
  </joint>

  <link name="link_2">
    <inertial>
      <origin xyz="0.5 0 0" rpy="0 0 0" />
      <mass value="1" />
      <inertia ixx="1" ixy="0" ixz="0" iyy="0.33" iyz="0" izz="1" />
    </inertial>
    <visual>
      <origin xyz="0.5 0 0 "/>
      <geometry>  <box size="1.0 0.05 0.05" /> </geometry>
      <material name="blue"> <color rgba="0 0 1 1" /> </material>
    </visual>
  </link>

  <joint name="joint_2_3" type="continuous">
    <parent link="link_2" />
    <child link="link_3" />
    <origin xyz="1.0 0.0 0" rpy="0.0 0 0 "/>
    <axis xyz="0 1 0" />
    <dynamics damping="0.1" />
  </joint>

  <link name="link_3">
    <inertial>
      <origin xyz="0.5 0 0" rpy="0 0 0" />
      <mass value="1" />
      <inertia ixx="1" ixy="0" ixz="0" iyy="0.33" iyz="0" izz="1" />
    </inertial>
    <visual>
      <origin xyz="0.5 0 0 "/>
      <geometry>  <box size="1.05 0.05 0.05" /> </geometry>
      <material name="green"> <color rgba="0 1 0 1" /> </material>
    </visual>
  </link>

  <joint name="joint_3_4" type="continuous">
    <parent link="link_3" />
    <child link="link_4" />
    <origin xyz="1.0 0.0 0" rpy="0.0 0 0 "/>
    <axis xyz="0 0 1" />
    <dynamics damping="0.1" />
  </joint>

  <link name="link_4">
    <inertial>
      <origin xyz="0.5 0 0" rpy="0 0 0" />
      <mass value="1" />
      <inertia ixx="1" ixy="0" ixz="0" iyy="0.33" iyz="0" izz="1" />
    </inertial>
    <visual>
      <origin xyz="0.5 0 0 "/>
      <geometry>  <box size="1.05 0.05 0.05" /> </geometry>
      <material name="red">  <color rgba="1 0 0 1" /></material>
    </visual>
  </link>

  <joint name="joint_4_5" type="continuous">
    <parent link="link_4" />
    <child link="link_5" />
    <origin xyz="1.0 0.0 0" rpy="0.0 0 0 "/>
    <axis xyz="0 1 0" />
    <dynamics damping="0.1" />
  </joint>

  <link name="link_5">
    <inertial>
      <origin xyz="0.5 0 0" rpy="0 0 0" />
      <mass value="1" />
      <inertia ixx="1" ixy="0" ixz="0" iyy="0.33" iyz="0" izz="1" />
    </inertial>
    <visual>
      <origin xyz="0.5 0 0 "/>
      <geometry>  <box size="1.05 0.05 0.05" /> </geometry>
      <material name="blue"> <color rgba="0 0 1 1" /> </material>
    </visual>
  </link>

  <joint name="joint_4_6" type="continuous">
    <parent link="link_4" />
    <child link="link_6" />
    <origin xyz="1.0 0.0 0" rpy="0.0 0 0 "/>
    <axis xyz="0 1 0" />
    <dynamics damping="0.1" />
  </joint>

  <link name="link_6">
    <inertial>
      <origin xyz="0.5 0 0" rpy="0 0 0" />
      <mass value="1" />
      <inertia ixx="1" ixy="0" ixz="0" iyy="0.33" iyz="0" izz="1" />
    </inertial>
    <visual>
      <origin xyz="0.5 0 0 "/>
      <geometry>  <box size="1.05 0.05 0.05" /> </geometry>
      <material name="blue"> <color rgba="0 0 1 1" /> </material>
    </visual>
  </link>

  <joint name="joint_5_7" type="continuous">
    <parent link="link_5" />
    <child link="link_7" />
    <origin xyz="1.0 0.0 0" rpy="0.0 0 0 "/>
    <axis xyz="0 1 0" />
    <dynamics damping="0.1" />
  </joint>

  <link name="link_7">
    <inertial>
      <origin xyz="0.5 0 0" rpy="0 0 0" />
      <mass value="1" />
      <inertia ixx="1" ixy="0" ixz="0" iyy="0.33" iyz="0" izz="1" />
    </inertial>
    <visual>
      <origin xyz="0.5 0 0 "/>
      <geometry>  <box size="1.05 0.05 0.05" /> </geometry>
      <material name="green"> <color rgba="0 1 0 1" /> </material>
    </visual>
  </link>

  <joint name="joint_6_8" type="continuous">
    <parent link="link_6" />
    <child link="link_8" />
    <origin xyz="1.0 0.0 0" rpy="0.0 0 0 "/>
    <axis xyz="0 1 0" />
    <dynamics damping="0.1" />
  </joint>

  <link name="link_8">
    <inertial>
      <origin xyz="0.5 0 0" rpy="0 0 0" />
      <mass value="1" />
      <inertia ixx="1" ixy="0" ixz="0" iyy="0.33" iyz="0" izz="1" />
    </inertial>
    <visual>
      <origin xyz="0.5 0 0 "/>
      <geometry>  <box size="1.05 0.05 0.05" /> </geometry>
      <material name="green"> <color rgba="0 1 0 1" /> </material>
    </visual>
  </link>


</robot>
